Workbook

Sheet Default
A1: ID | B1: Machine | C1: Groupe | D1: Automate | E1: type | F1: Nom | G1: Cause | H1: Solution | I1: Recherche
A2: 1 | B2: PMII | C2: Alarme | D2: Omron | E2: DEFAUT CAPTEUR | F2: Capteur HS | G2: =_xlfn.XLOOKUP(E2,liste!A:A,liste!B:B,"AUTRE") -> - Capteur mal aligné, mal réglé ou défectueux. - Problème de câblage ou de connecteur empêchant une bonne détection. | H2: =_xlfn.XLOOKUP(E2,liste!A:A,liste!C:C,"AUTRE") -> Vérifier le fonctionnement du capteur via ses voyants. Contrôler l’alignement, le réglage ainsi que l’état du câblage et des connecteurs. | I2: =A2 & " - " & B2 & " - " & C2 & " - " & D2 & " - " & E2 & " - " & F2 & " -" & H2 -> 1 - PMII - Alarme - Omron - DEFAUT CAPTEUR - Capteur HS - Vérifier le fonctionnement du capteur via ses voyants. Contrôler l’alignement, le réglage ainsi que l’état du câblage et des connecteurs.
A3: 2 | B3: PMAF | C3: Alarme | D3: M340 | E3: DEFAUT CAPTEUR | F3: DEFAUT CAPTEUR DECELERATION SUR LIFE (DT01) | G3: =_xlfn.XLOOKUP(E3,liste!A:A,liste!B:B,"AUTRE") -> - Capteur mal aligné, mal réglé ou défectueux. - Problème de câblage ou de connecteur empêchant une bonne détection. | H3: =_xlfn.XLOOKUP(E3,liste!A:A,liste!C:C,"AUTRE") -> Vérifier le fonctionnement du capteur via ses voyants. Contrôler l’alignement, le réglage ainsi que l’état du câblage et des connecteurs. | I3: =A3 & " - " & B3 & " - " & C3 & " - " & D3 & " - " & E3 & " - " & F3 & " -" & H3 -> 2 - PMAF - Alarme - M340 - DEFAUT CAPTEUR - DEFAUT CAPTEUR DECELERATION SUR LIFE (DT01) - Vérifier le fonctionnement du capteur via ses voyants. Contrôler l’alignement, le réglage ainsi que l’état du câblage et des connecteurs.
A4: 3 | B4: PMAF | C4: Alarme | D4: M340 | E4: DEFAUT CAPTEUR | F4: DEFAUT CAPTEUR PLATEAU EN POSITION SUR LIFE (DT02) | G4: =_xlfn.XLOOKUP(E4,liste!A:A,liste!B:B,"AUTRE") -> - Capteur mal aligné, mal réglé ou défectueux. - Problème de câblage ou de connecteur empêchant une bonne détection. | H4: =_xlfn.XLOOKUP(E4,liste!A:A,liste!C:C,"AUTRE") -> Vérifier le fonctionnement du capteur via ses voyants. Contrôler l’alignement, le réglage ainsi que l’état du câblage et des connecteurs. | I4: =A4 & " - " & B4 & " - " & C4 & " - " & D4 & " - " & E4 & " - " & F4 & " -" & H4 -> 3 - PMAF - Alarme - M340 - DEFAUT CAPTEUR - DEFAUT CAPTEUR PLATEAU EN POSITION SUR LIFE (DT02) - Vérifier le fonctionnement du capteur via ses voyants. Contrôler l’alignement, le réglage ainsi que l’état du câblage et des connecteurs.
A5: 4 | B5: PMAF | C5: Alarme | D5: M340 | E5: DEFAUT CAPTEUR | F5: DEFAUT CAPTEUR TOP PRISE N°1 (DT06) | G5: =_xlfn.XLOOKUP(E5,liste!A:A,liste!B:B,"AUTRE") -> - Capteur mal aligné, mal réglé ou défectueux. - Problème de câblage ou de connecteur empêchant une bonne détection. | H5: =_xlfn.XLOOKUP(E5,liste!A:A,liste!C:C,"AUTRE") -> Vérifier le fonctionnement du capteur via ses voyants. Contrôler l’alignement, le réglage ainsi que l’état du câblage et des connecteurs. | I5: =A5 & " - " & B5 & " - " & C5 & " - " & D5 & " - " & E5 & " - " & F5 & " -" & H5 -> 4 - PMAF - Alarme - M340 - DEFAUT CAPTEUR - DEFAUT CAPTEUR TOP PRISE N°1 (DT06) - Vérifier le fonctionnement du capteur via ses voyants. Contrôler l’alignement, le réglage ainsi que l’état du câblage et des connecteurs.
A6: 5 | B6: PMAF | C6: Alarme | D6: M340 | E6: DEFAUT CAPTEUR | F6: DEFAUT CAPTEUR TOP ENLEVEMENT (DT05) | G6: =_xlfn.XLOOKUP(E6,liste!A:A,liste!B:B,"AUTRE") -> - Capteur mal aligné, mal réglé ou défectueux. - Problème de câblage ou de connecteur empêchant une bonne détection. | H6: =_xlfn.XLOOKUP(E6,liste!A:A,liste!C:C,"AUTRE") -> Vérifier le fonctionnement du capteur via ses voyants. Contrôler l’alignement, le réglage ainsi que l’état du câblage et des connecteurs. | I6: =A6 & " - " & B6 & " - " & C6 & " - " & D6 & " - " & E6 & " - " & F6 & " -" & H6 -> 5 - PMAF - Alarme - M340 - DEFAUT CAPTEUR - DEFAUT CAPTEUR TOP ENLEVEMENT (DT05) - Vérifier le fonctionnement du capteur via ses voyants. Contrôler l’alignement, le réglage ainsi que l’état du câblage et des connecteurs.
A7: 6 | B7: PMAF | C7: Alarme | D7: M340 | E7: DEFAUT CAPTEUR | F7: DEFAUT CAPTEUR TOP PRISE N°2 (DT07) | G7: =_xlfn.XLOOKUP(E7,liste!A:A,liste!B:B,"AUTRE") -> - Capteur mal aligné, mal réglé ou défectueux. - Problème de câblage ou de connecteur empêchant une bonne détection. | H7: =_xlfn.XLOOKUP(E7,liste!A:A,liste!C:C,"AUTRE") -> Vérifier le fonctionnement du capteur via ses voyants. Contrôler l’alignement, le réglage ainsi que l’état du câblage et des connecteurs. | I7: =A7 & " - " & B7 & " - " & C7 & " - " & D7 & " - " & E7 & " - " & F7 & " -" & H7 -> 6 - PMAF - Alarme - M340 - DEFAUT CAPTEUR - DEFAUT CAPTEUR TOP PRISE N°2 (DT07) - Vérifier le fonctionnement du capteur via ses voyants. Contrôler l’alignement, le réglage ainsi que l’état du câblage et des connecteurs.
B8: PMAF | C8: Alarme | D8: M340 | E8: DEFAUT CAPTEUR | F8: DEFAUT CAPTEUR TOP PRISE N°3 (DT08) | G8: =_xlfn.XLOOKUP(E8,liste!A:A,liste!B:B,"AUTRE") -> - Capteur mal aligné, mal réglé ou défectueux. - Problème de câblage ou de connecteur empêchant une bonne détection. | H8: =_xlfn.XLOOKUP(E8,liste!A:A,liste!C:C,"AUTRE") -> Vérifier le fonctionnement du capteur via ses voyants. Contrôler l’alignement, le réglage ainsi que l’état du câblage et des connecteurs. | I8: =A8 & " - " & B8 & " - " & C8 & " - " & D8 & " - " & E8 & " - " & F8 & " -" & H8 -> - PMAF - Alarme - M340 - DEFAUT CAPTEUR - DEFAUT CAPTEUR TOP PRISE N°3 (DT08) - Vérifier le fonctionnement du capteur via ses voyants. Contrôler l’alignement, le réglage ainsi que l’état du câblage et des connecteurs.
B9: PMAF | C9: Alarme | D9: M340 | E9: DEFAUT CAMERA | F9: DEFAUT CAMERA1 | G9: =_xlfn.XLOOKUP(E9,liste!A:A,liste!B:B,"AUTRE") -> - trop d'oeuf mort détecté - camera sale ou endommagée | H9: =_xlfn.XLOOKUP(E9,liste!A:A,liste!C:C,"AUTRE") -> Vérifier que l'état des caméras | I9: =A9 & " - " & B9 & " - " & C9 & " - " & D9 & " - " & E9 & " - " & F9 & " -" & H9 -> - PMAF - Alarme - M340 - DEFAUT CAMERA - DEFAUT CAMERA1 -Vérifier que l'état des caméras
B10: PMAF | C10: Alarme | D10: M340 | E10: DEFAUT CAMERA | F10: DEFAUT CAMERA2 | G10: =_xlfn.XLOOKUP(E10,liste!A:A,liste!B:B,"AUTRE") -> - trop d'oeuf mort détecté - camera sale ou endommagée | H10: =_xlfn.XLOOKUP(E10,liste!A:A,liste!C:C,"AUTRE") -> Vérifier que l'état des caméras | I10: =A10 & " - " & B10 & " - " & C10 & " - " & D10 & " - " & E10 & " - " & F10 & " -" & H10 -> - PMAF - Alarme - M340 - DEFAUT CAMERA - DEFAUT CAMERA2 -Vérifier que l'état des caméras
B11: PMAF | C11: Alarme | D11: M340 | E11: DEFAUT CAMERA | F11: DEFAUT CAMERA3 | G11: =_xlfn.XLOOKUP(E11,liste!A:A,liste!B:B,"AUTRE") -> - trop d'oeuf mort détecté - camera sale ou endommagée | H11: =_xlfn.XLOOKUP(E11,liste!A:A,liste!C:C,"AUTRE") -> Vérifier que l'état des caméras | I11: =A11 & " - " & B11 & " - " & C11 & " - " & D11 & " - " & E11 & " - " & F11 & " -" & H11 -> - PMAF - Alarme - M340 - DEFAUT CAMERA - DEFAUT CAMERA3 -Vérifier que l'état des caméras
B12: PMAF | C12: Alarme | D12: M340 | E12: DEFAUT CAMERA | F12: DEFAUT CAMERA4 | G12: =_xlfn.XLOOKUP(E12,liste!A:A,liste!B:B,"AUTRE") -> - trop d'oeuf mort détecté - camera sale ou endommagée | H12: =_xlfn.XLOOKUP(E12,liste!A:A,liste!C:C,"AUTRE") -> Vérifier que l'état des caméras | I12: =A12 & " - " & B12 & " - " & C12 & " - " & D12 & " - " & E12 & " - " & F12 & " -" & H12 -> - PMAF - Alarme - M340 - DEFAUT CAMERA - DEFAUT CAMERA4 -Vérifier que l'état des caméras
B13: PMAF | C13: Alarme | D13: M340 | E13: DEFAUT CAMERA | F13: DEFAUT CAMERA5 | G13: =_xlfn.XLOOKUP(E13,liste!A:A,liste!B:B,"AUTRE") -> - trop d'oeuf mort détecté - camera sale ou endommagée | H13: =_xlfn.XLOOKUP(E13,liste!A:A,liste!C:C,"AUTRE") -> Vérifier que l'état des caméras | I13: =A13 & " - " & B13 & " - " & C13 & " - " & D13 & " - " & E13 & " - " & F13 & " -" & H13 -> - PMAF - Alarme - M340 - DEFAUT CAMERA - DEFAUT CAMERA5 -Vérifier que l'état des caméras
B14: PMAF | C14: Alarme | D14: M340 | E14: DEFAUT CAMERA | F14: DEFAUT CAMERA6 | G14: =_xlfn.XLOOKUP(E14,liste!A:A,liste!B:B,"AUTRE") -> - trop d'oeuf mort détecté - camera sale ou endommagée | H14: =_xlfn.XLOOKUP(E14,liste!A:A,liste!C:C,"AUTRE") -> Vérifier que l'état des caméras | I14: =A14 & " - " & B14 & " - " & C14 & " - " & D14 & " - " & E14 & " - " & F14 & " -" & H14 -> - PMAF - Alarme - M340 - DEFAUT CAMERA - DEFAUT CAMERA6 -Vérifier que l'état des caméras
B15: PMAF | C15: Alarme | D15: M340 | E15: DEFAUT CAPTEUR | F15: DEFAUT CAPTEUR TOP MIRAGE (DT03) | G15: =_xlfn.XLOOKUP(E15,liste!A:A,liste!B:B,"AUTRE") -> - Capteur mal aligné, mal réglé ou défectueux. - Problème de câblage ou de connecteur empêchant une bonne détection. | H15: =_xlfn.XLOOKUP(E15,liste!A:A,liste!C:C,"AUTRE") -> Vérifier le fonctionnement du capteur via ses voyants. Contrôler l’alignement, le réglage ainsi que l’état du câblage et des connecteurs. | I15: =A15 & " - " & B15 & " - " & C15 & " - " & D15 & " - " & E15 & " - " & F15 & " -" & H15 -> - PMAF - Alarme - M340 - DEFAUT CAPTEUR - DEFAUT CAPTEUR TOP MIRAGE (DT03) - Vérifier le fonctionnement du capteur via ses voyants. Contrôler l’alignement, le réglage ainsi que l’état du câblage et des connecteurs.
B16: PMAF | C16: Alarme | D16: M340 | E16: DEFAUT CR PC_PLC | F16: DEFAUT RETOUR CR PC_PLC | G16: =_xlfn.XLOOKUP(E16,liste!A:A,liste!B:B,"AUTRE") -> Crash ou mauvais démarrage de l'application PC : - Mauvaise connexion du PC à l'automate - Mauvaise connexion des caméra à l'automate - Problème PC (Saturation mémoire, crash ...) | H16: =_xlfn.XLOOKUP(E16,liste!A:A,liste!C:C,"AUTRE") -> Vérifier connexion des cables entre le PC, Camera et automate Redémarrer la machine | I16: =A16 & " - " & B16 & " - " & C16 & " - " & D16 & " - " & E16 & " - " & F16 & " -" & H16 -> - PMAF - Alarme - M340 - DEFAUT CR PC_PLC - DEFAUT RETOUR CR PC_PLC - Vérifier connexion des cables entre le PC, Camera et automate Redémarrer la machine
B17: PMAF | C17: Alarme | D17: M340 | E17: DEFAUT CAPTEUR | F17: DEFAUT CAPTEUR ESPACE LIBRE SORTIE MIRAGE (DT04) | G17: =_xlfn.XLOOKUP(E17,liste!A:A,liste!B:B,"AUTRE") -> - Capteur mal aligné, mal réglé ou défectueux. - Problème de câblage ou de connecteur empêchant une bonne détection. | H17: =_xlfn.XLOOKUP(E17,liste!A:A,liste!C:C,"AUTRE") -> Vérifier le fonctionnement du capteur via ses voyants. Contrôler l’alignement, le réglage ainsi que l’état du câblage et des connecteurs. | I17: =A17 & " - " & B17 & " - " & C17 & " - " & D17 & " - " & E17 & " - " & F17 & " -" & H17 -> - PMAF - Alarme - M340 - DEFAUT CAPTEUR - DEFAUT CAPTEUR ESPACE LIBRE SORTIE MIRAGE (DT04) - Vérifier le fonctionnement du capteur via ses voyants. Contrôler l’alignement, le réglage ainsi que l’état du câblage et des connecteurs.
B18: PMAF | C18: Alarme | D18: M340 | E18: PLATEAU MAUVAIS SENS | F18: PLATEAU DANS LE MAUVAIS SENS | G18: =_xlfn.XLOOKUP(E18,liste!A:A,liste!B:B,"AUTRE") -> - Plateau dans le mauvais sens - problème capteur de sens de plateau | H18: =_xlfn.XLOOKUP(E18,liste!A:A,liste!C:C,"AUTRE") -> Vérifier que le plateau est dans le bon sens Vérifier également que le capteur de sens de plateau est correctement réglé | I18: =A18 & " - " & B18 & " - " & C18 & " - " & D18 & " - " & E18 & " - " & F18 & " -" & H18 -> - PMAF - Alarme - M340 - PLATEAU MAUVAIS SENS - PLATEAU DANS LE MAUVAIS SENS -Vérifier que le plateau est dans le bon sens Vérifier également que le capteur de sens de plateau est correctement réglé
B19: PMAF | C19: Alarme | D19: M340 | E19: DEFAUT ONDULEUR | F19: DEFAUT ONDULEUR SUR ENLEVEMENT#1 | G19: =_xlfn.XLOOKUP(E19,liste!A:A,liste!B:B,"AUTRE") -> -Onduleur en défaut | H19: =_xlfn.XLOOKUP(E19,liste!A:A,liste!C:C,"AUTRE") -> Relever le défaut affiché sur l'onduleur Se référer à la documentation de celui ci pour résoudre le défaut | I19: =A19 & " - " & B19 & " - " & C19 & " - " & D19 & " - " & E19 & " - " & F19 & " -" & H19 -> - PMAF - Alarme - M340 - DEFAUT ONDULEUR - DEFAUT ONDULEUR SUR ENLEVEMENT#1 - Relever le défaut affiché sur l'onduleur Se référer à la documentation de celui ci pour résoudre le défaut
... B90: PMAF | C90: AlarmeE2 | D90: M340 | E90: DEFAUT PARAMETRE BRUSHLESS | F90: DEFAUT PARAMETRES BRUSHLESS A SAISIR ENLEVEMENT 2 | G90: =_xlfn.XLOOKUP(E90,liste!A:A,liste!B:B,"AUTRE") -> Paramètres définis dans le variateur incorrects | H90: =_xlfn.XLOOKUP(E90,liste!A:A,liste!C:C,"AUTRE") -> Vérification des paramètres variateur en fonction de l'actionneur | I90: =A90 & " - " & B90 & " - " & C90 & " - " & D90 & " - " & E90 & " - " & F90 & " -" & H90 -> - PMAF - AlarmeE2 - M340 - DEFAUT PARAMETRE BRUSHLESS - DEFAUT PARAMETRES BRUSHLESS A SAISIR ENLEVEMENT 2 -Vérification des paramètres variateur en fonction de l'actionneur

Sheet PMXA_BDD
A1: Nom | B1: ID d'alarme | C1: Code de l'événement | D1: Expression | E1: Message | F1: explication | G1: cause | H1: solution
A2: ArretUrgence | B2: Alarmes_Communes_ArretUrgence | C2: G001 | D2: AlarmesCommunes.ArretUrgence | E2: Défaut arrêt d'urgence | F2: =_xlfn.XLOOKUP("Explication_"&B2,Feuil2!B:B,Feuil2!C:C,"Non trouvé") -> La boucle électrique d'arrêt d'urgence du relais de sécurité a été ouverte | G2: =_xlfn.XLOOKUP("Cause_"&B2,Feuil2!B:B,Feuil2!C:C,"Non trouvé") -> - Au moins un bouton d'arrêt d'urgence a été enclenché - Si la machine vient d'être allumée, le défaut peut apparaître même si aucun bouton d'arrêt d'urgence n'a été enclenché | H2: =_xlfn.XLOOKUP("Solution_"&B2,Feuil2!B:B,Feuil2!C:C,"Non trouvé") -> Vérifier que les arrêts d'urgence de la machine sont désenclenchés, que les portes sont fermées, et appuyer sur le bouton "reset"
A3: DisjoncteurElectronique | B3: Alarmes_Communes_DisjoncteurElectronique | C3: G002 | D3: AlarmesCommunes.DisjoncteurElectronique | E3: Défaut disjoncteur éléctronique Q20 | F3: =_xlfn.XLOOKUP("Explication_"&B3,Feuil2!B:B,Feuil2!C:C,"Non trouvé") -> Une sortie du module de protection électronique Q20 s'est coupée car il y a eu une surintensité sur une de ses voies. | G3: =_xlfn.XLOOKUP("Cause_"&B3,Feuil2!B:B,Feuil2!C:C,"Non trouvé") -> - Mauvais réglage de l'intensité de la voie (le voyant passe en orange, puis en rouge) - Court-circuit sur la voie (le voyant passe directement en rouge) | H3: =_xlfn.XLOOKUP("Solution_"&B3,Feuil2!B:B,Feuil2!C:C,"Non trouvé") -> - Ajuster la protection thermique de la voie à l'aide de la vis proche du voyant - Eliminer le court-circuit puis appuyer sur le voyant du disjoncteur électronique pour réarmer la voie
A4: Onduleur | B4: Alarmes_Communes_Onduleur | C4: G003 | D4: AlarmesCommunes.Onduleur | E4: Défaut onduleur | F4: L'onduleur est en défaut | G4: L'onduleur est en défaut | H4: Relever le défaut sur l'écran du l'onduleur et se référer à la documentation de celui-ci
A5: OnduleurSurBatterie | B5: Alarmes_Communes_OnduleurSurBatterie | C5: G004 | D5: AlarmesCommunes.OnduleurSurBatterie | E5: Onduleur sur batterie | F5: =_xlfn.XLOOKUP("Explication_"&B5,Feuil2!B:B,Feuil2!C:C,"Non trouvé") -> L'onduleur ne détecte plus d'alimentation électrique et est passé en mode batterie, il renvoi un signal à l'automate | G5: =_xlfn.XLOOKUP("Cause_"&B5,Feuil2!B:B,Feuil2!C:C,"Non trouvé") -> Coupure de l'alimentation électrique de la machine (volontaire ou non) | H5: =_xlfn.XLOOKUP("Solution_"&B5,Feuil2!B:B,Feuil2!C:C,"Non trouvé") -> - Si le passage de l'onduleur sur batterie n'est pas normal ou n'est pas attendu, vérifier l'alimentation électrique de la machine jusqu’à l'onduleur. - Sinon, ne pas tenir compte de l'alarme, la machine va s'éteindre toute seule en quelques minutes.
A6: Parafoudre | B6: Alarmes_Communes_Parafoudre | C6: G005 | D6: AlarmesCommunes.Parafoudre | E6: Défaut parafoudre | F6: =_xlfn.XLOOKUP("Explication_"&B6,Feuil2!B:B,Feuil2!C:C,"Non trouvé") -> Le module parafoudre a au moins une cartouche hors service | G6: =_xlfn.XLOOKUP("Cause_"&B6,Feuil2!B:B,Feuil2!C:C,"Non trouvé") -> Surtension soudaine et importante sur l'alimentation générale de la machine. | H6: =_xlfn.XLOOKUP("Solution_"&B6,Feuil2!B:B,Feuil2!C:C,"Non trouvé") -> Remplacer la cartouche défectueuse.
A7: PressionAir | B7: Alarmes_Communes_PressionAir | C7: G006 | D7: AlarmesCommunes.PressionAir | E7: Défaut pressostat | F7: =_xlfn.XLOOKUP("Explication_"&B7,Feuil2!B:B,Feuil2!C:C,"Non trouvé") -> Le capteur de pression d'air général de la machine est hors plage de fonctionnement | G7: =_xlfn.XLOOKUP("Cause_"&B7,Feuil2!B:B,Feuil2!C:C,"Non trouvé") -> - Il n'y a pas d'air sur la machine (attention, le pressostat est situé en aval de la vanne de coupure générale), ou pas suffisamment - Le capteur de pression d'air est défectueux ou non alimenté | H7: =_xlfn.XLOOKUP("Solution_"&B7,Feuil2!B:B,Feuil2!C:C,"Non trouvé") -> - Vérifier la présence d'air comprimé en entrée de machine et que celle-ci soit dans la plage de tolérance acceptée - Si la valeur affichée à l'IHM est égale à 0 mais qu'il y a de l'air, vérifier que le capteur de pression est correctement alimenté électriquement. Si c'est le cas, remplacer-le.
A8: Tension | B8: Alarmes_Communes_Tension | C8: G007 | D8: AlarmesCommunes.Tension | E8: Défaut tension | F8: =_xlfn.XLOOKUP("Explication_"&B8,Feuil2!B:B,Feuil2!C:C,"Non trouvé") -> Non trouvé | G8: =_xlfn.XLOOKUP("Cause_"&B8,Feuil2!B:B,Feuil2!C:C,"Non trouvé") -> Non trouvé | H8: =_xlfn.XLOOKUP("Solution_"&B8,Feuil2!B:B,Feuil2!C:C,"Non trouvé") -> Non trouvé
A9: BatterieFaible | B9: Alarmes_Communes_BatterieFaible | C9: G008 | D9: AlarmesCommunes.BatterieFaible | E9: Batterie faible onduleur | F9: =_xlfn.XLOOKUP("Explication_"&B9,Feuil2!B:B,Feuil2!C:C,"Non trouvé") -> Non trouvé | G9: =_xlfn.XLOOKUP("Cause_"&B9,Feuil2!B:B,Feuil2!C:C,"Non trouvé") -> Non trouvé | H9: =_xlfn.XLOOKUP("Solution_"&B9,Feuil2!B:B,Feuil2!C:C,"Non trouvé") -> Non trouvé
A10: PasDePremierDemarrageValid | B10: Alarmes_Communes_PasDePremierDemarrageValid | C10: G009 | D10: AlarmesCommunes.PasDePremierDemarrageValide | E10: Premier démarrage non effectué | F10: =_xlfn.XLOOKUP("Explication_"&B10,Feuil2!B:B,Feuil2!C:C,"Non trouvé") -> L'automate détecte qu'il n'y a pas de valeurs dans les paramètres | G10: =_xlfn.XLOOKUP("Cause_"&B10,Feuil2!B:B,Feuil2!C:C,"Non trouvé") -> L'automate a perdu ses données | H10: =_xlfn.XLOOKUP("Solution_"&B10,Feuil2!B:B,Feuil2!C:C,"Non trouvé") -> Contacter Ecat-iD
A11: DetecttionPendantStressTest | B11: Alarmes_Communes_DetecttionPendantStressTest | C11: G010 | D11: Alarmes.DetectionPendantStressTest | E11: Défaut Détection contenant, Stress test stoppé | F11: =_xlfn.XLOOKUP("Explication_"&B11,Feuil2!B:B,Feuil2!C:C,"Non trouvé") -> Pendant le mode stress test, un capteur a détecté quelque chose et le mode s'est stoppé | G11: =_xlfn.XLOOKUP("Cause_"&B11,Feuil2!B:B,Feuil2!C:C,"Non trouvé") -> Quelque chose est passé devant un capteur pendant le mode stress test | H11: =_xlfn.XLOOKUP("Solution_"&B11,Feuil2!B:B,Feuil2!C:C,"Non trouvé") -> Vérifier les capteurs
A12: Com_Noeud1 | B12: Alarmes_Ethercat_Com_Noeud1 | C12: EC003 | D12: Alarmes.ComEthercat_Noeud1 | E12: Défaut de communication avec le noeud 1 : Port 1 du switch Ethercat | F12: =_xlfn.XLOOKUP("Explication_"&B12,Feuil2!B:B,Feuil2!C:C,"Non trouvé") -> Il y a un défaut de communication avec l'esclave Ethercat indiqué. Le voyant rouge du port Ethercat de l'automate clignote en rouge. | G12: =_xlfn.XLOOKUP("Cause_"&B12,Feuil2!B:B,Feuil2!C:C,"Non trouvé") -> - Une mauvaise connexion d'un câble Ethercat - L'esclave Ethercat n'est pas alimenté - Défaut du port Ethercat de l'automate | H12: =_xlfn.XLOOKUP("Solution_"&B12,Feuil2!B:B,Feuil2!C:C,"Non trouvé") -> - Vérifier l'état de l'esclave Ethercat en question à l'aide de la page de visualisation depuis l'IHM. - Si aucun défaut n'apparait sur l'esclave Ethercat, contacter ECATID
A13: Com_Noeud2 | B13: Alarmes_Ethercat_Com_Noeud2 | C13: EC004 | D13: Alarmes.ComEthercat_Noeud2 | E13: Défaut de communication avec le noeud 2 : Port 2 du switch Ethercat | F13: =_xlfn.XLOOKUP("Explication_"&B13,Feuil2!B:B,Feuil2!C:C,"Non trouvé") -> Il y a un défaut de communication avec l'esclave Ethercat indiqué. Le voyant rouge du port Ethercat de l'automate clignote en rouge. | G13: =_xlfn.XLOOKUP("Cause_"&B13,Feuil2!B:B,Feuil2!C:C,"Non trouvé") -> - Une mauvaise connexion d'un câble Ethercat - L'esclave Ethercat n'est pas alimenté - Défaut du port Ethercat de l'automate | H13: =_xlfn.XLOOKUP("Solution_"&B13,Feuil2!B:B,Feuil2!C:C,"Non trouvé") -> - Vérifier l'état de l'esclave Ethercat en question à l'aide de la page de visualisation depuis l'IHM. - Si aucun défaut n'apparait sur l'esclave Ethercat, contacter ECATID
A14: Com_Noeud30 | B14: Alarmes_Ethercat_Com_Noeud30 | C14: EC005 | D14: Alarmes.ComEthercat_Noeud30 | E14: Défaut de communication avec le noeud 30 : Variateur Convoyeur ligne de tri | F14: =_xlfn.XLOOKUP("Explication_"&B14,Feuil2!B:B,Feuil2!C:C,"Non trouvé") -> Il y a un défaut de communication avec l'esclave Ethercat indiqué. Le voyant rouge du port Ethercat de l'automate clignote en rouge. | G14: =_xlfn.XLOOKUP("Cause_"&B14,Feuil2!B:B,Feuil2!C:C,"Non trouvé") -> - Une mauvaise connexion d'un câble Ethercat - L'esclave Ethercat n'est pas alimenté - Défaut du port Ethercat de l'automate | H14: =_xlfn.XLOOKUP("Solution_"&B14,Feuil2!B:B,Feuil2!C:C,"Non trouvé") -> - Vérifier l'état de l'esclave Ethercat en question à l'aide de la page de visualisation depuis l'IHM. - Si aucun défaut n'apparait sur l'esclave Ethercat, contacter ECATID
A15: Com_Noeud31 | B15: Alarmes_Ethercat_Com_Noeud31 | C15: EC006 | D15: Alarmes.ComEthercat_Noeud31 | E15: Défaut de communication avec le noeud 31 : Variateur Convoyeur separateur | F15: =_xlfn.XLOOKUP("Explication_"&B15,Feuil2!B:B,Feuil2!C:C,"Non trouvé") -> Il y a un défaut de communication avec l'esclave Ethercat indiqué. Le voyant rouge du port Ethercat de l'automate clignote en rouge. | G15: =_xlfn.XLOOKUP("Cause_"&B15,Feuil2!B:B,Feuil2!C:C,"Non trouvé") -> - Une mauvaise connexion d'un câble Ethercat - L'esclave Ethercat n'est pas alimenté - Défaut du port Ethercat de l'automate | H15: =_xlfn.XLOOKUP("Solution_"&B15,Feuil2!B:B,Feuil2!C:C,"Non trouvé") -> - Vérifier l'état de l'esclave Ethercat en question à l'aide de la page de visualisation depuis l'IHM. - Si aucun défaut n'apparait sur l'esclave Ethercat, contacter ECATID
A16: Com_Noeud32 | B16: Alarmes_Ethercat_Com_Noeud32 | C16: EC007 | D16: Alarmes.ComEthercat_Noeud32 | E16: Défaut de communication avec le noeud 32 : Variateur Oscillation separateur | F16: =_xlfn.XLOOKUP("Explication_"&B16,Feuil2!B:B,Feuil2!C:C,"Non trouvé") -> Il y a un défaut de communication avec l'esclave Ethercat indiqué. Le voyant rouge du port Ethercat de l'automate clignote en rouge. | G16: =_xlfn.XLOOKUP("Cause_"&B16,Feuil2!B:B,Feuil2!C:C,"Non trouvé") -> - Une mauvaise connexion d'un câble Ethercat - L'esclave Ethercat n'est pas alimenté - Défaut du port Ethercat de l'automate | H16: =_xlfn.XLOOKUP("Solution_"&B16,Feuil2!B:B,Feuil2!C:C,"Non trouvé") -> - Vérifier l'état de l'esclave Ethercat en question à l'aide de la page de visualisation depuis l'IHM. - Si aucun défaut n'apparait sur l'esclave Ethercat, contacter ECATID
... A252: CapteurDeDebit_DefautFemelle | B252: Alarmes_Voies_Voie_6_CapteurDeDebit_DefautFemelle | C252: A627 | D252: Alarmes.CapteurDebit_DefautFemelleVoie(6) | E252: Défaut capteur de débit voie 6 | F252: =_xlfn.XLOOKUP("Explication_"&B252,Feuil2!B:B,Feuil2!C:C,"Non trouvé") -> Le débit d'air mesuré par le capteur de débit a été hors plage de fonctionnement pendant un certain nombre de fois. Ces codes sont pour l'aiguillage vers la voie extérieure. | G252: =_xlfn.XLOOKUP("Cause_"&B252,Feuil2!B:B,Feuil2!C:C,"Non trouvé") -> - Niveau d'air trop faible ou trop élevé - Electrovanne bouchée ou colmatée - Tuyau endommagé (plié, bouché, percé, etc…) | H252: =_xlfn.XLOOKUP("Solution_"&B252,Feuil2!B:B,Feuil2!C:C,"Non trouvé") -> - Contrôler le niveau d'air - Contrôler l'électrovanne - Contrôler le tuyau d'air - Changer l'électrovanne et / ou le tuyau si nécessaire

Sheet Feuil2
A1: RECOPIER A PARTIR DE LA LIGNE 3
A2: Group Name | B2: Resource ID | C2: Français (France) [fr-FR]
A3: [root] | B3: Explication_Alarmes_Communes_ArretUrgence | C3: La boucle électrique d'arrêt d'urgence du relais de sécurité a été ouverte
A4: [root] | B4: Explication_Alarmes_Communes_DisjoncteurElectronique | C4: Une sortie du module de protection électronique Q20 s'est coupée car il y a eu une surintensité sur une de ses voies.
A5: [root] | B5: Explication_Alarmes_Communes_OnduleurSurBatterie | C5: L'onduleur ne détecte plus d'alimentation électrique et est passé en mode batterie, il renvoi un signal à l'automate
A6: [root] | B6: Explication_Alarmes_Communes_Parafoudre | C6: Le module parafoudre a au moins une cartouche hors service
A7: [root] | B7: Explication_Alarmes_Communes_PressionAir | C7: Le capteur de pression d'air général de la machine est hors plage de fonctionnement
A8: [root] | B8: Explication_Alarmes_Communes_PasDePremierDemarrageValid | C8: L'automate détecte qu'il n'y a pas de valeurs dans les paramètres
A9: [root] | B9: Explication_Alarmes_Communes_DetecttionPendantStressTest | C9: Pendant le mode stress test, un capteur a détecté quelque chose et le mode s'est stoppé
A10: [root] | B10: Explication_Alarmes_Ethercat_Com_Noeud1 | C10: Il y a un défaut de communication avec l'esclave Ethercat indiqué. Le voyant rouge du port Ethercat de l'automate clignote en rouge.
A11: [root] | B11: Explication_Alarmes_Ethercat_Com_Noeud2 | C11: Il y a un défaut de communication avec l'esclave Ethercat indiqué. Le voyant rouge du port Ethercat de l'automate clignote en rouge.
A12: [root] | B12: Explication_Alarmes_Ethercat_Com_Noeud30 | C12: Il y a un défaut de communication avec l'esclave Ethercat indiqué. Le voyant rouge du port Ethercat de l'automate clignote en rouge.
A13: [root] | B13: Explication_Alarmes_Ethercat_Com_Noeud31 | C13: Il y a un défaut de communication avec l'esclave Ethercat indiqué. Le voyant rouge du port Ethercat de l'automate clignote en rouge.
... A632: [root] | B632: Solution_Alarmes_Voies_Voie_6_CapteurDeDebit_DefautFemelle | C632: - Contrôler le niveau d'air - Contrôler l'électrovanne - Contrôler le tuyau d'air - Changer l'électrovanne et / ou le tuyau si nécessaire

Sheet liste
A1: type | B1: Cause | C1: Résolution
A2: DEFAUT CAPTEUR | B2: - Capteur mal aligné, mal réglé ou défectueux. - Problème de câblage ou de connecteur empêchant une bonne détection. | C2: Vérifier le fonctionnement du capteur via ses voyants. Contrôler l’alignement, le réglage ainsi que l’état du câblage et des connecteurs.
A3: DEFAUT CAMERA | B3: - trop d'oeuf mort détecté - camera sale ou endommagée | C3: Vérifier que l'état des caméras
A4: DEFAUT CR PC_PLC | B4: Crash ou mauvais démarrage de l'application PC : - Mauvaise connexion du PC à l'automate - Mauvaise connexion des caméra à l'automate - Problème PC (Saturation mémoire, crash ...) | C4: Vérifier connexion des cables entre le PC, Camera et automate Redémarrer la machine
A5: PLATEAU MAUVAIS SENS | B5: - Plateau dans le mauvais sens - problème capteur de sens de plateau | C5: Vérifier que le plateau est dans le bon sens Vérifier également que le capteur de sens de plateau est correctement réglé
A6: DEFAUT ESCLAVE EMBASE PNEUMATIQUE | B6: Pas de bit de vie détecté : - Mauvaise connexion à l'embase pneumatique - Embase pneumatique défaillante | C6: Vérifier la connexion de l'embase pneumatique au PLC Vérifier le bon fonctionnement
A7: DEFAUT ONDULEUR | B7: -Onduleur en défaut | C7: Relever le défaut affiché sur l'onduleur Se référer à la documentation de celui ci pour résoudre le défaut
A8: DEFAUT COUPURE ALIMENTATION | B8: - L'équipement concerné est passé en mode batterie | C8: Vérifier la bonne alimentation de l'équipement.
A9: DEFAUT PLATEAUX COLLES | B9: - Plateau trop rapproché | C9: Vidanger les plateau de la machine Vérifier le bon fonctionnement des capteurs de plateau de la ligne
A10: DEFAUT ARRET D'URGENCE | B10: Au moins un élément de sécurité est enclenché. | C10: Vérifier les arrêt d’urgence et suivre la procédure de réarmement.
A11: DEFAUT VARIATEUR | B11: Le convoyeur n'est pas en fonctionnement Il y a un blocage mécanique sur l’élément ou condition non atteinte Le variateur renvoie un code défaut | C11: Vérifier le retour de marche du moteur. Contrôler le circuit électrique. Vérifier le montage mécanique. Vérifier le cycle Si moteur avec variateur : relever le code d'erreur sur le variateur puis se référer à la documentation de celui ci
A12: DEFAUT PORTE | B12: La porte n'est pas fermée | C12: Fermeture de la porte Capteur de capteur défectueux Câblage électrique défectueux
... A25: DEFAUT CONTROLE RETOUR BRUSHLESS | B25: La communication avec le variateur n'est plus établie ou a été coupée | C25: Vérifier l'alimentation des variateur Vérifier le câblage de communication Contrôler les architectures réseau

Sheet feuilleàmoi
A2: basé sur affaire C01509
A3: PMAF | B3: Alarme | C3: DEFAUT CAPTEUR DECELERATION SUR LIFE (DT01)
A4: PMAF | B4: Alarme | C4: DEFAUT CAPTEUR PLATEAU EN POSITION SUR LIFE (DT02)
A5: PMAF | B5: Alarme | C5: DEFAUT CAPTEUR TOP PRISE N°1 (DT06)
A6: PMAF | B6: Alarme | C6: DEFAUT CAPTEUR TOP ENLEVEMENT (DT05)
A7: PMAF | B7: Alarme | C7: DEFAUT CAPTEUR TOP PRISE N°2 (DT07)
A8: PMAF | B8: Alarme | C8: DEFAUT CAPTEUR TOP PRISE N°3 (DT08)
A9: PMAF | B9: Alarme | C9: DEFAUT CAMERA1
A10: PMAF | B10: Alarme | C10: DEFAUT CAMERA2
A11: PMAF | B11: Alarme | C11: DEFAUT CAMERA3
A12: PMAF | B12: Alarme | C12: DEFAUT CAMERA4
A13: PMAF | B13: Alarme | C13: DEFAUT CAMERA5
A14: PMAF | B14: Alarme | C14: DEFAUT CAMERA6
... A90: PMAF | B90: AlarmeE2 | C90: DEFAUT PARAMETRES BRUSHLESS A SAISIR ENLEVEMENT 2

Sheet PMXA_ancien
A1: ID | B1: Machine | C1: Groupe | D1: Automate | E1: type | F1: Nom | G1: explication | H1: Cause | I1: Solution | J1: Recherche
A2: G001 | B2: PMXA | C2: Alarme | D2: Omron | E2: DEFAUT ARRET D'URGENCE | F2: Défaut arrêt d'urgence | J2: =A2 & " - " & B2 & " - " & C2 & " - " & D2 & " - " & E2 & " - " & F2 & " -" & I2 -> G001 - PMXA - Alarme - Omron - DEFAUT ARRET D'URGENCE - Défaut arrêt d'urgence -
A3: G002 | B3: PMXA | C3: Alarme | D3: Omron | F3: Défaut disjoncteur éléctronique Q20 | J3: =A3 & " - " & B3 & " - " & C3 & " - " & D3 & " - " & E3 & " - " & F3 & " -" & I3 -> G002 - PMXA - Alarme - Omron - - Défaut disjoncteur éléctronique Q20 -
A4: G003 | B4: PMXA | C4: Alarme | D4: Omron | F4: Défaut onduleur | J4: =A4 & " - " & B4 & " - " & C4 & " - " & D4 & " - " & E4 & " - " & F4 & " -" & I4 -> G003 - PMXA - Alarme - Omron - - Défaut onduleur -
A5: G004 | B5: PMXA | C5: Alarme | D5: Omron | F5: Onduleur sur batterie | J5: =A5 & " - " & B5 & " - " & C5 & " - " & D5 & " - " & E5 & " - " & F5 & " -" & I5 -> G004 - PMXA - Alarme - Omron - - Onduleur sur batterie -
A6: G005 | B6: PMXA | C6: Alarme | D6: Omron | F6: Défaut parafoudre | J6: =A6 & " - " & B6 & " - " & C6 & " - " & D6 & " - " & E6 & " - " & F6 & " -" & I6 -> G005 - PMXA - Alarme - Omron - - Défaut parafoudre -
A7: G006 | B7: PMXA | C7: Alarme | D7: Omron | F7: Défaut pressostat | J7: =A7 & " - " & B7 & " - " & C7 & " - " & D7 & " - " & E7 & " - " & F7 & " -" & I7 -> G006 - PMXA - Alarme - Omron - - Défaut pressostat -
A8: G007 | B8: PMXA | C8: Alarme | D8: Omron | F8: Défaut tension | J8: =A8 & " - " & B8 & " - " & C8 & " - " & D8 & " - " & E8 & " - " & F8 & " -" & I8 -> G007 - PMXA - Alarme - Omron - - Défaut tension -
A9: G008 | B9: PMXA | C9: Alarme | D9: Omron | F9: Batterie faible onduleur | J9: =A9 & " - " & B9 & " - " & C9 & " - " & D9 & " - " & E9 & " - " & F9 & " -" & I9 -> G008 - PMXA - Alarme - Omron - - Batterie faible onduleur -
A10: G009 | B10: PMXA | C10: Alarme | D10: Omron | F10: Premier démarrage non effectué | J10: =A10 & " - " & B10 & " - " & C10 & " - " & D10 & " - " & E10 & " - " & F10 & " -" & I10 -> G009 - PMXA - Alarme - Omron - - Premier démarrage non effectué -
A11: G010 | B11: PMXA | C11: Alarme | D11: Omron | F11: Défaut Détection contenant, Stress test stoppé | J11: =A11 & " - " & B11 & " - " & C11 & " - " & D11 & " - " & E11 & " - " & F11 & " -" & I11 -> G010 - PMXA - Alarme - Omron - - Défaut Détection contenant, Stress test stoppé -
A12: EC003 | B12: PMXA | C12: Alarme | D12: Omron | F12: Défaut de communication avec le noeud 1 : Port 1 du switch Ethercat | I12: =_xlfn.XLOOKUP(E12,liste!A:A,liste!C:C,"AUTRE") -> 0 | J12: =#REF! & " - " & B12 & " - " & C12 & " - " & D12 & " - " & E12 & " - " & F12 & " -" & I12 -> #REF!
A13: EC004 | B13: PMXA | C13: Alarme | D13: Omron | F13: Défaut de communication avec le noeud 2 : Port 2 du switch Ethercat | I13: =_xlfn.XLOOKUP(E13,liste!A:A,liste!C:C,"AUTRE") -> 0 | J13: =#REF! & " - " & B13 & " - " & C13 & " - " & D13 & " - " & E13 & " - " & F13 & " -" & I13 -> #REF!
A14: EC005 | B14: PMXA | C14: Alarme | D14: Omron | F14: Défaut de communication avec le noeud 30 : Variateur Convoyeur ligne de tri | I14: =_xlfn.XLOOKUP(E14,liste!A:A,liste!C:C,"AUTRE") -> 0 | J14: =#REF! & " - " & B14 & " - " & C14 & " - " & D14 & " - " & E14 & " - " & F14 & " -" & I14 -> #REF!
A15: EC006 | B15: PMXA | C15: Alarme | D15: Omron | F15: Défaut de communication avec le noeud 31 : Variateur Convoyeur separateur | I15: =_xlfn.XLOOKUP(E15,liste!A:A,liste!C:C,"AUTRE") -> 0 | J15: =#REF! & " - " & B15 & " - " & C15 & " - " & D15 & " - " & E15 & " - " & F15 & " -" & I15 -> #REF!
A16: EC007 | B16: PMXA | C16: Alarme | D16: Omron | F16: Défaut de communication avec le noeud 32 : Variateur Oscillation separateur | I16: =_xlfn.XLOOKUP(E16,liste!A:A,liste!C:C,"AUTRE") -> 0 | J16: =#REF! & " - " & B16 & " - " & C16 & " - " & D16 & " - " & E16 & " - " & F16 & " -" & I16 -> #REF!
A17: EC008 | B17: PMXA | C17: Alarme | D17: Omron | F17: Défaut de communication avec le noeud 33 : Variateur Convoyeur accelerateur | I17: =_xlfn.XLOOKUP(E17,liste!A:A,liste!C:C,"AUTRE") -> 0 | J17: =#REF! & " - " & B17 & " - " & C17 & " - " & D17 & " - " & E17 & " - " & F17 & " -" & I17 -> #REF!
A18: EC009 | B18: PMXA | C18: Alarme | D18: Omron | F18: Défaut de communication avec le noeud 34 : Variateur Oscillation accelerateur | I18: =_xlfn.XLOOKUP(E18,liste!A:A,liste!C:C,"AUTRE") -> 0 | J18: =#REF! & " - " & B18 & " - " & C18 & " - " & D18 & " - " & E18 & " - " & F18 & " -" & I18 -> #REF!
A19: EC010 | B19: PMXA | C19: Alarme | D19: Omron | F19: Défaut de communication avec le noeud 35 : Variateur Convoyeur acquisition | I19: =_xlfn.XLOOKUP(E19,liste!A:A,liste!C:C,"AUTRE") -> 0 | J19: =#REF! & " - " & B19 & " - " & C19 & " - " & D19 & " - " & E19 & " - " & F19 & " -" & I19 -> #REF!
A20: EC011 | B20: PMXA | C20: Alarme | D20: Omron | F20: Défaut de communication avec le noeud 36 : Variateur Oscillation acquisition | I20: =_xlfn.XLOOKUP(E20,liste!A:A,liste!C:C,"AUTRE") -> 0 | J20: =#REF! & " - " & B20 & " - " & C20 & " - " & D20 & " - " & E20 & " - " & F20 & " -" & I20 -> #REF!
A21: EC012 | B21: PMXA | C21: Alarme | D21: Omron | F21: Défaut de communication avec le noeud 50 : Variateur Convoyeur entrée | I21: =_xlfn.XLOOKUP(E21,liste!A:A,liste!C:C,"AUTRE") -> 0 | J21: =#REF! & " - " & B21 & " - " & C21 & " - " & D21 & " - " & E21 & " - " & F21 & " -" & I21 -> #REF!
A22: EC002 | B22: PMXA | C22: Alarme | D22: Omron | F22: Défaut de communication Ethercat : nombre de tentatives de reset automatique atteint | I22: =_xlfn.XLOOKUP(E22,liste!A:A,liste!C:C,"AUTRE") -> 0 | J22: =#REF! & " - " & B22 & " - " & C22 & " - " & D22 & " - " & E22 & " - " & F22 & " -" & I22 -> #REF!
A23: EC001 | B23: PMXA | C23: Alarme | D23: Omron | F23: Défaut de communication sur réseau Ethercat | I23: =_xlfn.XLOOKUP(E23,liste!A:A,liste!C:C,"AUTRE") -> 0 | J23: =#REF! & " - " & B23 & " - " & C23 & " - " & D23 & " - " & E23 & " - " & F23 & " -" & I23 -> #REF!
... A31: EC008 | B31: PMXA | C31: Alarme | D31: Omron | F31: Défaut de communication avec le noeud 53 : Variateur Convoyeur entrée 4 | I31: =_xlfn.XLOOKUP(E31,liste!A:A,liste!C:C,"AUTRE") -> 0 | J31: =#REF! & " - " & B31 & " - " & C31 & " - " & D31 & " - " & E31 & " - " & F31 & " -" & I31 -> #REF!
A32: ES001 | B32: PMXA | C32: Alarme | D32: Omron | F32: Défaut sur la carte MOD 1 - Résoudre le problème, éteindre la machine et redémarrer après 30s | I32: =_xlfn.XLOOKUP(E32,liste!A:A,liste!C:C,"AUTRE") -> 0 | J32: =A32 & " - " & B32 & " - " & C32 & " - " & D32 & " - " & E32 & " - " & F32 & " -" & I32 -> ES001 - PMXA - Alarme - Omron - - Défaut sur la carte MOD 1 - Résoudre le problème, éteindre la machine et redémarrer après 30s -0
A33: ES002 | B33: PMXA | C33: Alarme | D33: Omron | F33: Défaut sur la carte MOD 2 - Résoudre le problème, éteindre la machine et redémarrer après 30s | I33: =_xlfn.XLOOKUP(E33,liste!A:A,liste!C:C,"AUTRE") -> 0 | J33: =A33 & " - " & B33 & " - " & C33 & " - " & D33 & " - " & E33 & " - " & F33 & " -" & I33 -> ES002 - PMXA - Alarme - Omron - - Défaut sur la carte MOD 2 - Résoudre le problème, éteindre la machine et redémarrer après 30s -0
A34: ES003 | B34: PMXA | C34: Alarme | D34: Omron | F34: Défaut sur la carte MOD 3 - Résoudre le problème, éteindre la machine et redémarrer après 30s | I34: =_xlfn.XLOOKUP(E34,liste!A:A,liste!C:C,"AUTRE") -> 0 | J34: =A34 & " - " & B34 & " - " & C34 & " - " & D34 & " - " & E34 & " - " & F34 & " -" & I34 -> ES003 - PMXA - Alarme - Omron - - Défaut sur la carte MOD 3 - Résoudre le problème, éteindre la machine et redémarrer après 30s -0
A35: ES004 | B35: PMXA | C35: Alarme | D35: Omron | F35: Défaut sur la carte MOD 4 - Résoudre le problème, éteindre la machine et redémarrer après 30s | I35: =_xlfn.XLOOKUP(E35,liste!A:A,liste!C:C,"AUTRE") -> 0 | J35: =A35 & " - " & B35 & " - " & C35 & " - " & D35 & " - " & E35 & " - " & F35 & " -" & I35 -> ES004 - PMXA - Alarme - Omron - - Défaut sur la carte MOD 4 - Résoudre le problème, éteindre la machine et redémarrer après 30s -0
A36: ES005 | B36: PMXA | C36: Alarme | D36: Omron | F36: Défaut sur la carte MOD 5 - Résoudre le problème, éteindre la machine et redémarrer après 30s | I36: =_xlfn.XLOOKUP(E36,liste!A:A,liste!C:C,"AUTRE") -> 0 | J36: =A36 & " - " & B36 & " - " & C36 & " - " & D36 & " - " & E36 & " - " & F36 & " -" & I36 -> ES005 - PMXA - Alarme - Omron - - Défaut sur la carte MOD 5 - Résoudre le problème, éteindre la machine et redémarrer après 30s -0
A37: ES006 | B37: PMXA | C37: Alarme | D37: Omron | F37: Défaut sur la carte MOD 6 - Résoudre le problème, éteindre la machine et redémarrer après 30s | I37: =_xlfn.XLOOKUP(E37,liste!A:A,liste!C:C,"AUTRE") -> 0 | J37: =A37 & " - " & B37 & " - " & C37 & " - " & D37 & " - " & E37 & " - " & F37 & " -" & I37 -> ES006 - PMXA - Alarme - Omron - - Défaut sur la carte MOD 6 - Résoudre le problème, éteindre la machine et redémarrer après 30s -0
A38: ES007 | B38: PMXA | C38: Alarme | D38: Omron | F38: Défaut sur la carte MOD 7 - Résoudre le problème, éteindre la machine et redémarrer après 30s | I38: =_xlfn.XLOOKUP(E38,liste!A:A,liste!C:C,"AUTRE") -> 0 | J38: =A38 & " - " & B38 & " - " & C38 & " - " & D38 & " - " & E38 & " - " & F38 & " -" & I38 -> ES007 - PMXA - Alarme - Omron - - Défaut sur la carte MOD 7 - Résoudre le problème, éteindre la machine et redémarrer après 30s -0
A39: ES008 | B39: PMXA | C39: Alarme | D39: Omron | F39: Défaut sur la carte MOD 8 - Résoudre le problème, éteindre la machine et redémarrer après 30s | I39: =_xlfn.XLOOKUP(E39,liste!A:A,liste!C:C,"AUTRE") -> 0 | J39: =A39 & " - " & B39 & " - " & C39 & " - " & D39 & " - " & E39 & " - " & F39 & " -" & I39 -> ES008 - PMXA - Alarme - Omron - - Défaut sur la carte MOD 8 - Résoudre le problème, éteindre la machine et redémarrer après 30s -0
A40: ES009 | B40: PMXA | C40: Alarme | D40: Omron | F40: Défaut sur la carte MOD 9 - Résoudre le problème, éteindre la machine et redémarrer après 30s | I40: =_xlfn.XLOOKUP(E40,liste!A:A,liste!C:C,"AUTRE") -> 0 | J40: =A40 & " - " & B40 & " - " & C40 & " - " & D40 & " - " & E40 & " - " & F40 & " -" & I40 -> ES009 - PMXA - Alarme - Omron - - Défaut sur la carte MOD 9 - Résoudre le problème, éteindre la machine et redémarrer après 30s -0
A41: ES010 | B41: PMXA | C41: Alarme | D41: Omron | F41: Défaut sur la carte MOD 10 - Résoudre le problème, éteindre la machine et redémarrer après 30s | I41: =_xlfn.XLOOKUP(E41,liste!A:A,liste!C:C,"AUTRE") -> 0 | J41: =A41 & " - " & B41 & " - " & C41 & " - " & D41 & " - " & E41 & " - " & F41 & " -" & I41 -> ES010 - PMXA - Alarme - Omron - - Défaut sur la carte MOD 10 - Résoudre le problème, éteindre la machine et redémarrer après 30s -0
A42: ES011 | B42: PMXA | C42: Alarme | D42: Omron | F42: Défaut sur la carte MOD 11 - Résoudre le problème, éteindre la machine et redémarrer après 30s | I42: =_xlfn.XLOOKUP(E42,liste!A:A,liste!C:C,"AUTRE") -> 0 | J42: =A42 & " - " & B42 & " - " & C42 & " - " & D42 & " - " & E42 & " - " & F42 & " -" & I42 -> ES011 - PMXA - Alarme - Omron - - Défaut sur la carte MOD 11 - Résoudre le problème, éteindre la machine et redémarrer après 30s -0
A43: A001 | F43: Défaut intensité Convoyeur ligne de tri | I43: =_xlfn.XLOOKUP(E43,liste!A:A,liste!C:C,"AUTRE") -> 0 | J43: =A43 & " - " & B43 & " - " & C43 & " - " & D43 & " - " & E43 & " - " & F43 & " -" & I43 -> A001 - - - - - Défaut intensité Convoyeur ligne de tri -0
A44: A002 | F44: Défaut Convoyeur ligne de tri | I44: =_xlfn.XLOOKUP(E44,liste!A:A,liste!C:C,"AUTRE") -> 0 | J44: =A44 & " - " & B44 & " - " & C44 & " - " & D44 & " - " & E44 & " - " & F44 & " -" & I44 -> A002 - - - - - Défaut Convoyeur ligne de tri -0
A45: A003 | F45: Défaut intensité Convoyeur séparateur | I45: =_xlfn.XLOOKUP(E45,liste!A:A,liste!C:C,"AUTRE") -> 0 | J45: =A45 & " - " & B45 & " - " & C45 & " - " & D45 & " - " & E45 & " - " & F45 & " -" & I45 -> A003 - - - - - Défaut intensité Convoyeur séparateur -0
A46: A004 | F46: Défaut Convoyeur séparateur | I46: =_xlfn.XLOOKUP(E46,liste!A:A,liste!C:C,"AUTRE") -> 0 | J46: =A46 & " - " & B46 & " - " & C46 & " - " & D46 & " - " & E46 & " - " & F46 & " -" & I46 -> A004 - - - - - Défaut Convoyeur séparateur -0
A47: A005 | F47: Défaut intensité Convoyeur accélérateur | I47: =_xlfn.XLOOKUP(E47,liste!A:A,liste!C:C,"AUTRE") -> 0 | J47: =A47 & " - " & B47 & " - " & C47 & " - " & D47 & " - " & E47 & " - " & F47 & " -" & I47 -> A005 - - - - - Défaut intensité Convoyeur accélérateur -0
...
